<?xml version="1.0" encoding="UTF-8"?>
<testng-results skipped="2" failed="6" total="12" passed="4">
  <reporter-output>
  </reporter-output>
  <suite name="Default suite" duration-ms="69" started-at="2015-07-13T11:53:24Z" finished-at="2015-07-13T11:53:24Z">
    <groups>
      <group name="important">
        <method signature="FailingCases.MinusTest(int, int)[pri:0, instance:com.comarch.training.FailingCases@5a39699c]" name="MinusTest" class="com.comarch.training.FailingCases"/>
      </group> <!-- important -->
      <group name="failures">
        <method signature="FailingCases.MinusTest(int, int)[pri:0, instance:com.comarch.training.FailingCases@5a39699c]" name="MinusTest" class="com.comarch.training.FailingCases"/>
        <method signature="FailingCases.AddingTest(int, int)[pri:0, instance:com.comarch.training.FailingCases@5a39699c]" name="AddingTest" class="com.comarch.training.FailingCases"/>
        <method signature="FailingCases.MultiplyTest(int, int)[pri:0, instance:com.comarch.training.FailingCases@5a39699c]" name="MultiplyTest" class="com.comarch.training.FailingCases"/>
      </group> <!-- failures -->
    </groups>
    <test name="Default test" duration-ms="69" started-at="2015-07-13T11:53:24Z" finished-at="2015-07-13T11:53:24Z">
      <class name="com.comarch.training.FailingCases">
        <test-method status="PASS" signature="init()[pri:0, instance:com.comarch.training.FailingCases@5a39699c]" name="init" is-config="true" duration-ms="9" started-at="2015-07-13T13:53:24Z" finished-at="2015-07-13T13:53:24Z">
          <reporter-output>
          </reporter-output>
        </test-method> <!-- init -->
        <test-method status="FAIL" signature="MinusTest(int, int)[pri:0, instance:com.comarch.training.FailingCases@5a39699c]" name="MinusTest" duration-ms="7" started-at="2015-07-13T13:53:24Z" data-provider="TwoArgs" finished-at="2015-07-13T13:53:24Z">
          <params>
            <param index="0">
              <value>
                <![CDATA[10]]>
              </value>
            </param>
            <param index="1">
              <value>
                <![CDATA[5]]>
              </value>
            </param>
          </params>
          <exception class="java.lang.AssertionError">
            <message>
              <![CDATA[expected [6] but found [5]]]>
            </message>
            <full-stacktrace>
              <![CDATA[java.lang.AssertionError: expected [6] but found [5]
	at org.testng.Assert.fail(Assert.java:94)
	at org.testng.Assert.failNotEquals(Assert.java:496)
	at org.testng.Assert.assertEquals(Assert.java:125)
	at org.testng.Assert.assertEquals(Assert.java:372)
	at org.testng.Assert.assertEquals(Assert.java:382)
	at com.comarch.training.FailingCases.MinusTest(FailingCases.java:28)
	at sun.reflect.NativeMethodAccessorImpl.invoke0(Native Method)
	at sun.reflect.NativeMethodAccessorImpl.invoke(Unknown Source)
	at sun.reflect.DelegatingMethodAccessorImpl.invoke(Unknown Source)
	at java.lang.reflect.Method.invoke(Unknown Source)
	at org.testng.internal.MethodInvocationHelper.invokeMethod(MethodInvocationHelper.java:85)
	at org.testng.internal.Invoker.invokeMethod(Invoker.java:659)
	at org.testng.internal.Invoker.invokeTestMethod(Invoker.java:845)
	at org.testng.internal.Invoker.invokeTestMethods(Invoker.java:1153)
	at org.testng.internal.TestMethodWorker.invokeTestMethods(TestMethodWorker.java:125)
	at org.testng.internal.TestMethodWorker.run(TestMethodWorker.java:108)
	at org.testng.TestRunner.privateRun(TestRunner.java:771)
	at org.testng.TestRunner.run(TestRunner.java:621)
	at org.testng.SuiteRunner.runTest(SuiteRunner.java:357)
	at org.testng.SuiteRunner.runSequentially(SuiteRunner.java:352)
	at org.testng.SuiteRunner.privateRun(SuiteRunner.java:310)
	at org.testng.SuiteRunner.run(SuiteRunner.java:259)
	at org.testng.SuiteRunnerWorker.runSuite(SuiteRunnerWorker.java:52)
	at org.testng.SuiteRunnerWorker.run(SuiteRunnerWorker.java:86)
	at org.testng.TestNG.runSuitesSequentially(TestNG.java:1199)
	at org.testng.TestNG.runSuitesLocally(TestNG.java:1124)
	at org.testng.TestNG.run(TestNG.java:1032)
	at org.testng.remote.RemoteTestNG.run(RemoteTestNG.java:111)
	at org.testng.remote.RemoteTestNG.initAndRun(RemoteTestNG.java:204)
	at org.testng.remote.RemoteTestNG.main(RemoteTestNG.java:175)
]]>
            </full-stacktrace>
          </exception> <!-- java.lang.AssertionError -->
          <reporter-output>
          </reporter-output>
        </test-method> <!-- MinusTest -->
        <test-method status="PASS" signature="MinusTest(int, int)[pri:0, instance:com.comarch.training.FailingCases@5a39699c]" name="MinusTest" duration-ms="1" started-at="2015-07-13T13:53:24Z" data-provider="TwoArgs" finished-at="2015-07-13T13:53:24Z">
          <params>
            <param index="0">
              <value>
                <![CDATA[2]]>
              </value>
            </param>
            <param index="1">
              <value>
                <![CDATA[5]]>
              </value>
            </param>
          </params>
          <reporter-output>
          </reporter-output>
        </test-method> <!-- MinusTest -->
        <test-method status="FAIL" signature="MinusTest(int, int)[pri:0, instance:com.comarch.training.FailingCases@5a39699c]" name="MinusTest" duration-ms="1" started-at="2015-07-13T13:53:24Z" data-provider="TwoArgs" finished-at="2015-07-13T13:53:24Z">
          <params>
            <param index="0">
              <value>
                <![CDATA[7]]>
              </value>
            </param>
            <param index="1">
              <value>
                <![CDATA[6]]>
              </value>
            </param>
          </params>
          <exception class="java.lang.AssertionError">
            <message>
              <![CDATA[expected [2] but found [1]]]>
            </message>
            <full-stacktrace>
              <![CDATA[java.lang.AssertionError: expected [2] but found [1]
	at org.testng.Assert.fail(Assert.java:94)
	at org.testng.Assert.failNotEquals(Assert.java:496)
	at org.testng.Assert.assertEquals(Assert.java:125)
	at org.testng.Assert.assertEquals(Assert.java:372)
	at org.testng.Assert.assertEquals(Assert.java:382)
	at com.comarch.training.FailingCases.MinusTest(FailingCases.java:28)
	at sun.reflect.NativeMethodAccessorImpl.invoke0(Native Method)
	at sun.reflect.NativeMethodAccessorImpl.invoke(Unknown Source)
	at sun.reflect.DelegatingMethodAccessorImpl.invoke(Unknown Source)
	at java.lang.reflect.Method.invoke(Unknown Source)
	at org.testng.internal.MethodInvocationHelper.invokeMethod(MethodInvocationHelper.java:85)
	at org.testng.internal.Invoker.invokeMethod(Invoker.java:659)
	at org.testng.internal.Invoker.invokeTestMethod(Invoker.java:845)
	at org.testng.internal.Invoker.invokeTestMethods(Invoker.java:1153)
	at org.testng.internal.TestMethodWorker.invokeTestMethods(TestMethodWorker.java:125)
	at org.testng.internal.TestMethodWorker.run(TestMethodWorker.java:108)
	at org.testng.TestRunner.privateRun(TestRunner.java:771)
	at org.testng.TestRunner.run(TestRunner.java:621)
	at org.testng.SuiteRunner.runTest(SuiteRunner.java:357)
	at org.testng.SuiteRunner.runSequentially(SuiteRunner.java:352)
	at org.testng.SuiteRunner.privateRun(SuiteRunner.java:310)
	at org.testng.SuiteRunner.run(SuiteRunner.java:259)
	at org.testng.SuiteRunnerWorker.runSuite(SuiteRunnerWorker.java:52)
	at org.testng.SuiteRunnerWorker.run(SuiteRunnerWorker.java:86)
	at org.testng.TestNG.runSuitesSequentially(TestNG.java:1199)
	at org.testng.TestNG.runSuitesLocally(TestNG.java:1124)
	at org.testng.TestNG.run(TestNG.java:1032)
	at org.testng.remote.RemoteTestNG.run(RemoteTestNG.java:111)
	at org.testng.remote.RemoteTestNG.initAndRun(RemoteTestNG.java:204)
	at org.testng.remote.RemoteTestNG.main(RemoteTestNG.java:175)
]]>
            </full-stacktrace>
          </exception> <!-- java.lang.AssertionError -->
          <reporter-output>
          </reporter-output>
        </test-method> <!-- MinusTest -->
        <test-method status="FAIL" signature="MinusTest(int, int)[pri:0, instance:com.comarch.training.FailingCases@5a39699c]" name="MinusTest" duration-ms="1" started-at="2015-07-13T13:53:24Z" data-provider="TwoArgs" finished-at="2015-07-13T13:53:24Z">
          <params>
            <param index="0">
              <value>
                <![CDATA[7]]>
              </value>
            </param>
            <param index="1">
              <value>
                <![CDATA[6]]>
              </value>
            </param>
          </params>
          <exception class="java.lang.AssertionError">
            <message>
              <![CDATA[expected [2] but found [1]]]>
            </message>
            <full-stacktrace>
              <![CDATA[java.lang.AssertionError: expected [2] but found [1]
	at org.testng.Assert.fail(Assert.java:94)
	at org.testng.Assert.failNotEquals(Assert.java:496)
	at org.testng.Assert.assertEquals(Assert.java:125)
	at org.testng.Assert.assertEquals(Assert.java:372)
	at org.testng.Assert.assertEquals(Assert.java:382)
	at com.comarch.training.FailingCases.MinusTest(FailingCases.java:28)
	at sun.reflect.NativeMethodAccessorImpl.invoke0(Native Method)
	at sun.reflect.NativeMethodAccessorImpl.invoke(Unknown Source)
	at sun.reflect.DelegatingMethodAccessorImpl.invoke(Unknown Source)
	at java.lang.reflect.Method.invoke(Unknown Source)
	at org.testng.internal.MethodInvocationHelper.invokeMethod(MethodInvocationHelper.java:85)
	at org.testng.internal.Invoker.invokeMethod(Invoker.java:659)
	at org.testng.internal.Invoker.invokeTestMethod(Invoker.java:845)
	at org.testng.internal.Invoker.invokeTestMethods(Invoker.java:1153)
	at org.testng.internal.TestMethodWorker.invokeTestMethods(TestMethodWorker.java:125)
	at org.testng.internal.TestMethodWorker.run(TestMethodWorker.java:108)
	at org.testng.TestRunner.privateRun(TestRunner.java:771)
	at org.testng.TestRunner.run(TestRunner.java:621)
	at org.testng.SuiteRunner.runTest(SuiteRunner.java:357)
	at org.testng.SuiteRunner.runSequentially(SuiteRunner.java:352)
	at org.testng.SuiteRunner.privateRun(SuiteRunner.java:310)
	at org.testng.SuiteRunner.run(SuiteRunner.java:259)
	at org.testng.SuiteRunnerWorker.runSuite(SuiteRunnerWorker.java:52)
	at org.testng.SuiteRunnerWorker.run(SuiteRunnerWorker.java:86)
	at org.testng.TestNG.runSuitesSequentially(TestNG.java:1199)
	at org.testng.TestNG.runSuitesLocally(TestNG.java:1124)
	at org.testng.TestNG.run(TestNG.java:1032)
	at org.testng.remote.RemoteTestNG.run(RemoteTestNG.java:111)
	at org.testng.remote.RemoteTestNG.initAndRun(RemoteTestNG.java:204)
	at org.testng.remote.RemoteTestNG.main(RemoteTestNG.java:175)
]]>
            </full-stacktrace>
          </exception> <!-- java.lang.AssertionError -->
          <reporter-output>
          </reporter-output>
        </test-method> <!-- MinusTest -->
        <test-method status="FAIL" signature="MinusTest(int, int)[pri:0, instance:com.comarch.training.FailingCases@5a39699c]" name="MinusTest" duration-ms="1" started-at="2015-07-13T13:53:24Z" data-provider="TwoArgs" finished-at="2015-07-13T13:53:24Z">
          <params>
            <param index="0">
              <value>
                <![CDATA[-2]]>
              </value>
            </param>
            <param index="1">
              <value>
                <![CDATA[11]]>
              </value>
            </param>
          </params>
          <exception class="java.lang.AssertionError">
            <message>
              <![CDATA[expected [-12] but found [-13]]]>
            </message>
            <full-stacktrace>
              <![CDATA[java.lang.AssertionError: expected [-12] but found [-13]
	at org.testng.Assert.fail(Assert.java:94)
	at org.testng.Assert.failNotEquals(Assert.java:496)
	at org.testng.Assert.assertEquals(Assert.java:125)
	at org.testng.Assert.assertEquals(Assert.java:372)
	at org.testng.Assert.assertEquals(Assert.java:382)
	at com.comarch.training.FailingCases.MinusTest(FailingCases.java:28)
	at sun.reflect.NativeMethodAccessorImpl.invoke0(Native Method)
	at sun.reflect.NativeMethodAccessorImpl.invoke(Unknown Source)
	at sun.reflect.DelegatingMethodAccessorImpl.invoke(Unknown Source)
	at java.lang.reflect.Method.invoke(Unknown Source)
	at org.testng.internal.MethodInvocationHelper.invokeMethod(MethodInvocationHelper.java:85)
	at org.testng.internal.Invoker.invokeMethod(Invoker.java:659)
	at org.testng.internal.Invoker.invokeTestMethod(Invoker.java:845)
	at org.testng.internal.Invoker.invokeTestMethods(Invoker.java:1153)
	at org.testng.internal.TestMethodWorker.invokeTestMethods(TestMethodWorker.java:125)
	at org.testng.internal.TestMethodWorker.run(TestMethodWorker.java:108)
	at org.testng.TestRunner.privateRun(TestRunner.java:771)
	at org.testng.TestRunner.run(TestRunner.java:621)
	at org.testng.SuiteRunner.runTest(SuiteRunner.java:357)
	at org.testng.SuiteRunner.runSequentially(SuiteRunner.java:352)
	at org.testng.SuiteRunner.privateRun(SuiteRunner.java:310)
	at org.testng.SuiteRunner.run(SuiteRunner.java:259)
	at org.testng.SuiteRunnerWorker.runSuite(SuiteRunnerWorker.java:52)
	at org.testng.SuiteRunnerWorker.run(SuiteRunnerWorker.java:86)
	at org.testng.TestNG.runSuitesSequentially(TestNG.java:1199)
	at org.testng.TestNG.runSuitesLocally(TestNG.java:1124)
	at org.testng.TestNG.run(TestNG.java:1032)
	at org.testng.remote.RemoteTestNG.run(RemoteTestNG.java:111)
	at org.testng.remote.RemoteTestNG.initAndRun(RemoteTestNG.java:204)
	at org.testng.remote.RemoteTestNG.main(RemoteTestNG.java:175)
]]>
            </full-stacktrace>
          </exception> <!-- java.lang.AssertionError -->
          <reporter-output>
          </reporter-output>
        </test-method> <!-- MinusTest -->
        <test-method status="PASS" signature="MinusTest(int, int)[pri:0, instance:com.comarch.training.FailingCases@5a39699c]" name="MinusTest" duration-ms="1" started-at="2015-07-13T13:53:24Z" data-provider="TwoArgs" finished-at="2015-07-13T13:53:24Z">
          <params>
            <param index="0">
              <value>
                <![CDATA[17]]>
              </value>
            </param>
            <param index="1">
              <value>
                <![CDATA[222]]>
              </value>
            </param>
          </params>
          <reporter-output>
          </reporter-output>
        </test-method> <!-- MinusTest -->
        <test-method status="FAIL" signature="MinusTest(int, int)[pri:0, instance:com.comarch.training.FailingCases@5a39699c]" name="MinusTest" duration-ms="1" started-at="2015-07-13T13:53:24Z" data-provider="TwoArgs" finished-at="2015-07-13T13:53:24Z">
          <params>
            <param index="0">
              <value>
                <![CDATA[-7]]>
              </value>
            </param>
            <param index="1">
              <value>
                <![CDATA[14]]>
              </value>
            </param>
          </params>
          <exception class="java.lang.AssertionError">
            <message>
              <![CDATA[expected [-20] but found [-21]]]>
            </message>
            <full-stacktrace>
              <![CDATA[java.lang.AssertionError: expected [-20] but found [-21]
	at org.testng.Assert.fail(Assert.java:94)
	at org.testng.Assert.failNotEquals(Assert.java:496)
	at org.testng.Assert.assertEquals(Assert.java:125)
	at org.testng.Assert.assertEquals(Assert.java:372)
	at org.testng.Assert.assertEquals(Assert.java:382)
	at com.comarch.training.FailingCases.MinusTest(FailingCases.java:28)
	at sun.reflect.NativeMethodAccessorImpl.invoke0(Native Method)
	at sun.reflect.NativeMethodAccessorImpl.invoke(Unknown Source)
	at sun.reflect.DelegatingMethodAccessorImpl.invoke(Unknown Source)
	at java.lang.reflect.Method.invoke(Unknown Source)
	at org.testng.internal.MethodInvocationHelper.invokeMethod(MethodInvocationHelper.java:85)
	at org.testng.internal.Invoker.invokeMethod(Invoker.java:659)
	at org.testng.internal.Invoker.invokeTestMethod(Invoker.java:845)
	at org.testng.internal.Invoker.invokeTestMethods(Invoker.java:1153)
	at org.testng.internal.TestMethodWorker.invokeTestMethods(TestMethodWorker.java:125)
	at org.testng.internal.TestMethodWorker.run(TestMethodWorker.java:108)
	at org.testng.TestRunner.privateRun(TestRunner.java:771)
	at org.testng.TestRunner.run(TestRunner.java:621)
	at org.testng.SuiteRunner.runTest(SuiteRunner.java:357)
	at org.testng.SuiteRunner.runSequentially(SuiteRunner.java:352)
	at org.testng.SuiteRunner.privateRun(SuiteRunner.java:310)
	at org.testng.SuiteRunner.run(SuiteRunner.java:259)
	at org.testng.SuiteRunnerWorker.runSuite(SuiteRunnerWorker.java:52)
	at org.testng.SuiteRunnerWorker.run(SuiteRunnerWorker.java:86)
	at org.testng.TestNG.runSuitesSequentially(TestNG.java:1199)
	at org.testng.TestNG.runSuitesLocally(TestNG.java:1124)
	at org.testng.TestNG.run(TestNG.java:1032)
	at org.testng.remote.RemoteTestNG.run(RemoteTestNG.java:111)
	at org.testng.remote.RemoteTestNG.initAndRun(RemoteTestNG.java:204)
	at org.testng.remote.RemoteTestNG.main(RemoteTestNG.java:175)
]]>
            </full-stacktrace>
          </exception> <!-- java.lang.AssertionError -->
          <reporter-output>
          </reporter-output>
        </test-method> <!-- MinusTest -->
        <test-method status="FAIL" signature="MinusTest(int, int)[pri:0, instance:com.comarch.training.FailingCases@5a39699c]" name="MinusTest" duration-ms="1" started-at="2015-07-13T13:53:24Z" data-provider="TwoArgs" finished-at="2015-07-13T13:53:24Z">
          <params>
            <param index="0">
              <value>
                <![CDATA[-7]]>
              </value>
            </param>
            <param index="1">
              <value>
                <![CDATA[2]]>
              </value>
            </param>
          </params>
          <exception class="java.lang.AssertionError">
            <message>
              <![CDATA[expected [-8] but found [-9]]]>
            </message>
            <full-stacktrace>
              <![CDATA[java.lang.AssertionError: expected [-8] but found [-9]
	at org.testng.Assert.fail(Assert.java:94)
	at org.testng.Assert.failNotEquals(Assert.java:496)
	at org.testng.Assert.assertEquals(Assert.java:125)
	at org.testng.Assert.assertEquals(Assert.java:372)
	at org.testng.Assert.assertEquals(Assert.java:382)
	at com.comarch.training.FailingCases.MinusTest(FailingCases.java:28)
	at sun.reflect.NativeMethodAccessorImpl.invoke0(Native Method)
	at sun.reflect.NativeMethodAccessorImpl.invoke(Unknown Source)
	at sun.reflect.DelegatingMethodAccessorImpl.invoke(Unknown Source)
	at java.lang.reflect.Method.invoke(Unknown Source)
	at org.testng.internal.MethodInvocationHelper.invokeMethod(MethodInvocationHelper.java:85)
	at org.testng.internal.Invoker.invokeMethod(Invoker.java:659)
	at org.testng.internal.Invoker.invokeTestMethod(Invoker.java:845)
	at org.testng.internal.Invoker.invokeTestMethods(Invoker.java:1153)
	at org.testng.internal.TestMethodWorker.invokeTestMethods(TestMethodWorker.java:125)
	at org.testng.internal.TestMethodWorker.run(TestMethodWorker.java:108)
	at org.testng.TestRunner.privateRun(TestRunner.java:771)
	at org.testng.TestRunner.run(TestRunner.java:621)
	at org.testng.SuiteRunner.runTest(SuiteRunner.java:357)
	at org.testng.SuiteRunner.runSequentially(SuiteRunner.java:352)
	at org.testng.SuiteRunner.privateRun(SuiteRunner.java:310)
	at org.testng.SuiteRunner.run(SuiteRunner.java:259)
	at org.testng.SuiteRunnerWorker.runSuite(SuiteRunnerWorker.java:52)
	at org.testng.SuiteRunnerWorker.run(SuiteRunnerWorker.java:86)
	at org.testng.TestNG.runSuitesSequentially(TestNG.java:1199)
	at org.testng.TestNG.runSuitesLocally(TestNG.java:1124)
	at org.testng.TestNG.run(TestNG.java:1032)
	at org.testng.remote.RemoteTestNG.run(RemoteTestNG.java:111)
	at org.testng.remote.RemoteTestNG.initAndRun(RemoteTestNG.java:204)
	at org.testng.remote.RemoteTestNG.main(RemoteTestNG.java:175)
]]>
            </full-stacktrace>
          </exception> <!-- java.lang.AssertionError -->
          <reporter-output>
          </reporter-output>
        </test-method> <!-- MinusTest -->
        <test-method status="PASS" signature="MinusTest(int, int)[pri:0, instance:com.comarch.training.FailingCases@5a39699c]" name="MinusTest" duration-ms="0" started-at="2015-07-13T13:53:24Z" data-provider="TwoArgs" finished-at="2015-07-13T13:53:24Z">
          <params>
            <param index="0">
              <value>
                <![CDATA[1]]>
              </value>
            </param>
            <param index="1">
              <value>
                <![CDATA[-4]]>
              </value>
            </param>
          </params>
          <reporter-output>
          </reporter-output>
        </test-method> <!-- MinusTest -->
        <test-method status="PASS" signature="MinusTest(int, int)[pri:0, instance:com.comarch.training.FailingCases@5a39699c]" name="MinusTest" duration-ms="0" started-at="2015-07-13T13:53:24Z" data-provider="TwoArgs" finished-at="2015-07-13T13:53:24Z">
          <params>
            <param index="0">
              <value>
                <![CDATA[0]]>
              </value>
            </param>
            <param index="1">
              <value>
                <![CDATA[-5]]>
              </value>
            </param>
          </params>
          <reporter-output>
          </reporter-output>
        </test-method> <!-- MinusTest -->
        <test-method status="SKIP" signature="AddingTest(int, int)[pri:0, instance:com.comarch.training.FailingCases@5a39699c]" name="AddingTest" duration-ms="0" depends-on-groups="important" started-at="2015-07-13T13:53:24Z" data-provider="TwoArgs" finished-at="2015-07-13T13:53:24Z">
          <exception class="java.lang.Throwable">
            <message>
              <![CDATA[Method FailingCases.AddingTest(int, int)[pri:0, instance:com.comarch.training.FailingCases@5a39699c] depends on not successfully finished methods in group "important"]]>
            </message>
            <full-stacktrace>
              <![CDATA[java.lang.Throwable: Method FailingCases.AddingTest(int, int)[pri:0, instance:com.comarch.training.FailingCases@5a39699c] depends on not successfully finished methods in group "important"
	at org.testng.internal.Invoker.invokeTestMethods(Invoker.java:1063)
	at org.testng.internal.TestMethodWorker.invokeTestMethods(TestMethodWorker.java:125)
	at org.testng.internal.TestMethodWorker.run(TestMethodWorker.java:108)
	at org.testng.TestRunner.privateRun(TestRunner.java:771)
	at org.testng.TestRunner.run(TestRunner.java:621)
	at org.testng.SuiteRunner.runTest(SuiteRunner.java:357)
	at org.testng.SuiteRunner.runSequentially(SuiteRunner.java:352)
	at org.testng.SuiteRunner.privateRun(SuiteRunner.java:310)
	at org.testng.SuiteRunner.run(SuiteRunner.java:259)
	at org.testng.SuiteRunnerWorker.runSuite(SuiteRunnerWorker.java:52)
	at org.testng.SuiteRunnerWorker.run(SuiteRunnerWorker.java:86)
	at org.testng.TestNG.runSuitesSequentially(TestNG.java:1199)
	at org.testng.TestNG.runSuitesLocally(TestNG.java:1124)
	at org.testng.TestNG.run(TestNG.java:1032)
	at org.testng.remote.RemoteTestNG.run(RemoteTestNG.java:111)
	at org.testng.remote.RemoteTestNG.initAndRun(RemoteTestNG.java:204)
	at org.testng.remote.RemoteTestNG.main(RemoteTestNG.java:175)
]]>
            </full-stacktrace>
          </exception> <!-- java.lang.Throwable -->
          <reporter-output>
          </reporter-output>
        </test-method> <!-- AddingTest -->
        <test-method status="SKIP" signature="MultiplyTest(int, int)[pri:0, instance:com.comarch.training.FailingCases@5a39699c]" name="MultiplyTest" duration-ms="0" depends-on-groups="important" started-at="2015-07-13T13:53:24Z" data-provider="TwoArgs" finished-at="2015-07-13T13:53:24Z">
          <exception class="java.lang.Throwable">
            <message>
              <![CDATA[Method FailingCases.MultiplyTest(int, int)[pri:0, instance:com.comarch.training.FailingCases@5a39699c] depends on not successfully finished methods in group "important"]]>
            </message>
            <full-stacktrace>
              <![CDATA[java.lang.Throwable: Method FailingCases.MultiplyTest(int, int)[pri:0, instance:com.comarch.training.FailingCases@5a39699c] depends on not successfully finished methods in group "important"
	at org.testng.internal.Invoker.invokeTestMethods(Invoker.java:1063)
	at org.testng.internal.TestMethodWorker.invokeTestMethods(TestMethodWorker.java:125)
	at org.testng.internal.TestMethodWorker.run(TestMethodWorker.java:108)
	at org.testng.TestRunner.privateRun(TestRunner.java:771)
	at org.testng.TestRunner.run(TestRunner.java:621)
	at org.testng.SuiteRunner.runTest(SuiteRunner.java:357)
	at org.testng.SuiteRunner.runSequentially(SuiteRunner.java:352)
	at org.testng.SuiteRunner.privateRun(SuiteRunner.java:310)
	at org.testng.SuiteRunner.run(SuiteRunner.java:259)
	at org.testng.SuiteRunnerWorker.runSuite(SuiteRunnerWorker.java:52)
	at org.testng.SuiteRunnerWorker.run(SuiteRunnerWorker.java:86)
	at org.testng.TestNG.runSuitesSequentially(TestNG.java:1199)
	at org.testng.TestNG.runSuitesLocally(TestNG.java:1124)
	at org.testng.TestNG.run(TestNG.java:1032)
	at org.testng.remote.RemoteTestNG.run(RemoteTestNG.java:111)
	at org.testng.remote.RemoteTestNG.initAndRun(RemoteTestNG.java:204)
	at org.testng.remote.RemoteTestNG.main(RemoteTestNG.java:175)
]]>
            </full-stacktrace>
          </exception> <!-- java.lang.Throwable -->
          <reporter-output>
          </reporter-output>
        </test-method> <!-- MultiplyTest -->
      </class> <!-- com.comarch.training.FailingCases -->
    </test> <!-- Default test -->
  </suite> <!-- Default suite -->
</testng-results>
